# 错误处理

## 错误类型
 开发中常见的错误：
> 语法错误  
> 逻辑错误  
> 运行时错误 （可能会导致崩溃，也叫做异常）  

## 自定义错误  
> swift 中可以通过error协议自定义运行时的错误信息
  		enum SomeError: Error {
  			case illegal(String)
  			case outofBounds(Int, Int)
  			case outofMemory
  		}
 
> 函数内部通过throw抛出自定义Error，可能会抛出Error的函数必须声明为throws  
		
		func divide(_ num1: Int, _ num2: Int) throws -> Int {
			if num2 == 0 {
				throw SomeError. illegal("0不能作为参数")
			}
			return num1/num2
		
		}  
> 需要使用try调用可能会抛出Error的函数
		
		var result = try divide(20, 10)  

## do catch  
> 可以使用do catch 捕捉Error  
	
	func test() {
		print("1")
		do {
		 	print("2")
		 	let result = try divide(20, 0)
		 	print(result)
			print("3")
		} catch let SomeError.illegal(msg) {
			print("参数错误 \(msg)")
		} catch let SomeError.outofBounds(size, index) {
			print("下标越界size = \(size) index = \(index)")
		} catch SomeError.outofMemory {
			print("内存溢出")
		} catch {
			print("位置错误")
		}
	}
	
	test()
	
	do {
		let result = try divide(20, 0)
		print(result)
	} catch let error {
		switch error {
		case let SomeError.illegal(msg) :
			print("参数错误 \(msg)")
		case let SomeError.outofBounds(size, index) :
			print("下标越界size = \(size) index = \(index)")
		default:
			print("位置错误")
		}
	}
	
## 处理error  
处理error的方式有两种  
> 通过do catch 捕获  
> 不通过error，在当前函数增加throws声明，error会自动抛给上层函数。如果上层函数依然没有捕获error，那么程序将会终止
## try？ try！  
可以使用try？、try！调用可能会抛出Error的函数，这样就不用去处理Error 
		
		func test() {
			print("1")
			var result1 = try? divide(20, 10) //Optional(2) 
			var result2 = try? divide(20, 0)  // nil
			var result3 = try! divide(20, 10) // 2
			print("2")
		}
		test()  
> a、b 是等价的  
		
		var a = try? divide(20, 0)  
		var b: Int? 
		do {
			b = try divide(20, 0)
		} catch { b = nil }  
		
## rethrows  
> rethrows 表明： 函数本身不会抛出错误，但是闭包参数会抛出错误，那么他会将错误向上抛出  
		
		func exec(_ fn:(Int, Int) throws -> Int, _ num1: Int, _ num2: Int) rethrows {
			 print(try fn(num1, num2))
		}

		try exec(divide, 20, 0) //  SomeError - illegal : "0不能作为参数" 
## defer  
> defer语句： 用来定义以任何方式（抛错误、return等）离开代码块前必须要执行的代码  
> defer语句将延迟至当前作用域结束之前执行  
		
		func open(_ filename: String) -> Int {
			print("open")
			return 0
		}
		func close(_ file: Int) {
			print("close")
		}
		func processFile(_ filename: String) throws {
			let file = open(filename)
			defer {
				close(file)
		}
   	 		print("close exec in here")
    		try divide(20, 0)
    		// close 在这里执行
		}
		try processFile("hello world.txt")
> defer 语句执行顺序和定义顺序相反  
		
		func fn1() { print("fn1") }
		func fn2() { print("fn2") }
		func test() { 
			defer{ fn1() }
			defer{ fn2() }
		 }
		 test() // fn2 , fn1 
## assert  
> 很多编程语言都有断言机制：不符合指定条件就抛出运行时错误，常用于调试（Debug）阶段的条件判断  
> 默认情况下，swift的断言只会在Debug模式下生效，release模式下忽略  
		
		func divide(_ v1: Int, _ v2: Int) -> Int {
			assert(v2 != 0, "除数不能为0") 
			return v1/v2 
		}  
		print(divide(20, 0))
## fatalError  
> 如果遇到严重问题， 希望结束程序运行时，可以直接fatalError函数抛出错误（这时无法通过do catch捕捉错误 ）   
> 使用了fatalError函数，就不需要再写return  
		
		func test(_ num: Int) -> Int {
			if num >= 0 {
				return 1
			}
			fatalError("num 不能小于0")
		}  
> 在某些不得不实现、但不希望别人调用的方法，可以考虑内部使用fatalError函数  

		class Person {
			required init() {}
		}
		class Student: Person {
			required init() {
				fatalError("don't call student init")
    	}
    		init(score: Int) {}
		}
		var stu1 = Student(score: 98)
		var stu2 = Student()
		
## 局部作用域  
> 可以使用do实现局部作用域  
 		
 		do {
 			let dog1 = Dog()
 			dog1.age = 10
 			dog1.run()
 		}
 		
 		do {
			let dog2 = Dog()
			dog2.age = 10
			dog2.run() 		
 		}
